<?xml version='1.0'?>

<robot name="slam_project" xmlns:xacro="http://www.ros.org/wiki/xacro">
  <xacro:include filename="$(find slam_project)/urdf/realsense-RS200.macro.xacro"/>
  <link name="robot_footprint"></link>

  <joint name="robot_footprint_joint" type="fixed">
    <origin xyz="0 0 0" rpy="0 0 0" />
    <parent link="robot_footprint"/>
    <child link="chassis" />
  </joint>

  <link name='chassis'>
    <pose>0 0 0.1 0 0 0</pose>

    <inertial>
      <mass value="15.0"/>
      <origin xyz="0.0 0 0" rpy=" 0 0 0"/>
      <inertia
          ixx="0.1" ixy="0" ixz="0"
          iyy="0.1" iyz="0"
          izz="0.1"
      />
    </inertial>

    <collision name='collision'>
      <origin xyz="0 0 0" rpy=" 0 0 0"/> 
      <geometry>
        <box size=".4 .2 .1"/>
      </geometry>
    </collision>

    <visual name='chassis_visual'>
      <origin xyz="0 0 0" rpy=" 0 0 0"/>
      <geometry>
        <box size=".4 .2 .1"/>
      </geometry>
      <material name="black"/>
    </visual>


    <collision name='back_caster_collision'>
      <origin xyz="-0.15 0 -0.05" rpy=" 0 0 0"/>
      <geometry>
        <sphere radius="0.0499"/>
      </geometry>
    </collision>

    <visual name='back_caster_visual'>
      <origin xyz="-0.15 0 -0.05" rpy=" 0 0 0"/>
      <geometry>
        <sphere radius="0.05"/>
      </geometry>
    </visual>

    <collision name='front_caster_collision'>
      <origin xyz="0.15 0 -0.05" rpy=" 0 0 0"/>
      <geometry>
        <sphere radius="0.0499"/>
      </geometry>
    </collision>

    <visual name='front_caster_visual'>
      <origin xyz="0.15 0 -0.05" rpy=" 0 0 0"/>
      <geometry>
        <sphere radius="0.05"/>
      </geometry>
    </visual>

  </link>
  <xacro:macro name="default_inertial" params="mass">
      <inertial>
              <mass value="${mass}" />
              <inertia ixx="0.1" ixy="0.0" ixz="0.0"
                    iyy="0.1" iyz="0.0"
                    izz="0.1" />
      </inertial>
  </xacro:macro>

  
  <xacro:property name="wheelradius" value="0.1" />
  <xacro:property name="wheellength" value="0.05" />
  <xacro:property name="mass" value="5.0" />
  <xacro:macro name="wheel" params="prefix reflect">
      <link name="${prefix}_wheel">
          <visual>
              <geometry>
                  <cylinder radius="${wheelradius}" length="${wheellength}"/>
              </geometry>
              <origin xyz="0 0 0" rpy="0 ${pi/2} ${pi/2}"/>
              <material name="blue"/>
          </visual>
          <collision>
              <geometry>
                  <cylinder radius="${wheelradius}" length="${wheellength}"/>
              </geometry>
              <origin xyz="0 0 0" rpy="0 ${pi/2} ${pi/2}"/>
          </collision>
          <xacro:default_inertial mass="5.0"/>
          
      </link>

      <joint name="${prefix}_wheel_hinge" type="continuous">
          <parent link="chassis"/>
          <child link="${prefix}_wheel"/>
          <axis xyz="0 1 0" rpy="0 0 0"/>
          <origin xyz="0 ${reflect*0.15} 0" rpy="0 0 0"/>
          <limit effort="10000" velocity="1000"/>
          <dynamics damping="1.0" friction="1.0"/>
      </joint>
      <!-- A bunch of stuff cut -->
  </xacro:macro>
  
  <xacro:wheel prefix="right" reflect="-1" />
  <xacro:wheel prefix="left" reflect="1" />


  <link name="camera_support_link">
		<visual name="camera_support_visual">
			<origin xyz="0 0 0" rpy="0 0 0"/>
			<geometry>
				<box size=".05 .05 .8"/>
			</geometry>
		</visual>

		<collision name="camera_support_collision">
			<origin xyz="0 0 0" rpy="0 0 0"/>
			<geometry>
				<box size="0.05 0.05 0.8"/>
			</geometry>
		</collision>

		<inertial>
        <mass value="0.1"/>
        <origin xyz="0 0 0" rpy="0 0 0"/>
        <inertia
                ixx="1e-6" ixy="0" ixz="0"
                iyy="1e-6" iyz="0"
                izz="1e-6"
        />
    </inertial>
	</link>
    <!-- Create camera instance -->
    <xacro:realsense-rs200/>

  <joint name="camera_support_joint" type="fixed">
    <origin xyz="0.0 0.0 0.4" rpy="0.0 0.0 0.0"/>
    <parent link="chassis"/>
    <child link="camera_support_link"/>
    <limit effort="1000" velocity="100"/>
  </joint>

  <joint name="camera_joint" type="fixed">
    <origin xyz="0.0 0.0 0.42" rpy="0.0 0.0 0.0"/>
    <parent link="camera_support_link"/>
    <child link="rs200_camera"/>
    <limit effort="1000" velocity="100"/>
  </joint>


  <link name="hokuyo">
		<visual name="hokuyo_visual">
			<origin xyz="0 0 0" rpy="0 0 0"/>
			<geometry>
				<mesh filename="package://slam_project/meshes/hokuyo.dae"/>
			</geometry>
		</visual>

		<collision name="hokuyo_collision">
			<origin xyz="0 0 0" rpy="0 0 0"/>
			<geometry>
				<box size="0.1 0.1 0.1"/>
			</geometry>
		</collision>

		<inertial>
        <mass value="0.1"/>
        <origin xyz="0 0 0" rpy="0 0 0"/>
        <inertia
                ixx="1e-6" ixy="0" ixz="0"
                iyy="1e-6" iyz="0"
                izz="1e-6"
        />
    </inertial>
	</link>

	<joint name="hokuyo_joint" type="fixed">
		<origin xyz="0.15 0 0.1" rpy="0 0 0"/>
		<parent link="chassis"/>
		<child link="hokuyo"/>
	</joint>


</robot>

	